Workbook

Sheet BSPR RAS metrics
B1: 42401 | W1: ACTION PLAN OWNER | AC1: PR - BSPR | BR1: Sensitivity | BS1: 0.5
C2: SHUSA RISK APPETITE METRICS | D2: 2015 TRIGGER LIMIT | E2: 2015 RED LIMIT | F2: SOURCE FOR 2016 RAS LIMIT SETTING | H2: SHUSA IN GROUP RAS | I2: 2016 TRIGGER LIMIT | J2: 2016 RED LIMIT | L2: SHUSA US RAS | M2: 2016 TRIGGER LIMIT | N2: 2016 RED LIMIT | P2: BSPR | Q2: 2016 TRIGGER LIMIT | R2: 2016 RED LIMIT | T2: COMMENTS | U2: GROUP DEFINITION | V2: ACTION PLAN | W2: LINE 1 | X2: LINE 2 | Y2: BSPR Comments | Z2: Metric Applicability Confirmed with SHUSA | AA2: Calibration Comments | AC2: Frequency | AD2: Current RTS / RSC metric | AE2: SAN-PR Definition | AF2: SOURCE FOR 2016 RAS LIMIT SETTING | AG2: Source | AH2: Availability | AI2: Level | AJ2: Rationale for threshold definition | AK2: Budget | AL2: Reports Affected | AM2: Reports Consistency Validation | AN2: Differences: SHUSA RAS Glossary vs. BSPR Methodology | AO2: 2015 TRIGGER LIMIT | AP2: 2015 RED LIMIT | AQ2: 2016 GREEN | AR2: 2016 TRIGGER LIMIT | AS2: 2016 RED LIMIT | AT2: 42035 | AU2: 42063 | AV2: 42094 | AW2: 42124 | AX2: 42155 | AY2: 42185 | AZ2: 42216 | BA2: 42247 | BB2: 42277 | BC2: 42308 | BD2: 42338 | BE2: 42369 | BF2: 42400 | BG2: 42401 | BH2: 42430 | BI2: 42461 | BJ2: 42491 | BK2: 42522 | BL2: 42552 | BM2: 42583 | BN2: 42614 | BO2: 42644 | BP2: 42675 | BQ2: 42705 | BR2: Average | BS2: Variance | BT2: Standard Deviation | BU2: AVS | BV2: Local Comments - Cristina's Review | BW2: Comparación 4/8/16
B3: Capital | C3: Common Equity Tier 1 Ratio | D3: 0.11 | E3: 0.105 | F3: Capital Mgmt Group | H3: Y | L3: Y | P3: Y | T3: SIS will report its regulatory ratios. Pending receipt of list and levels | Z3: YES | AC3: Monthly | AD3: RTS BSPR #0048 | AE3: A measurement of core equity capital compared with its total risk-weighted assets. The Tier 1 common capital ratio excludes any preferred shares or non-controlling interests when determining the calculation. | AF3: Leslie Adames (threshold calibration) Comptrollership / Hector Ramos (monthly data) | AG3: ALTAIR system | AH3: Available on day 10th of each month. | AI3: Capital Policy | AJ3: Capital Policy from November 27, 2015 which was approved by the Board on December 8, 2015. Information is located in page 7, Table 3: 2015 SBC/BSPR Capital Expectations. the Planned capital hold was considered for the Amber trigger and the Business-as-usual was consideredfor the Red limit. | AL3: ALCO Risk Scorecard Quarterly Capital Trends | AM3: ALCO: December 2015 and January 2016 OK Quarterly: March. June and September 2015 OK | AO3: 0.1208 | AP3: 0.106 | AR3: 0.1301 | AS3: 0.1101 | AT3: =(881.62-75)/3824.4 -> 0.21091413 | AU3: =(882.69-75)/3827.05 -> 0.21104767 | AV3: =(886.92-75)/3744.03 -> 0.21685724 | AW3: =(890.75234096-75)/3767.184 -> 0.21654168 | AX3: =(893.64630978-75)/3827.715 -> 0.21387337 | AY3: =(896.87773133-75)/3854.980185 -> 0.21319895 | AZ3: =(899.32698133-75)/3832.377 -> 0.21509548 | BA3: =(902.33900133-75)/3790.394 -> 0.21827256 | BB3: =(905.02-75)/3617.54 -> 0.22944321 | BC3: =(906.32-75)/3601.15 -> 0.23084848 | BD3: =(908.344820238001-75)/3544.49459731878 -> 0.23510963 | BE3: =(917.054273058005-75)/3567.9148400942 -> 0.23600739 | BF3: =(845.303335227995-0)/3515.04 -> 0.24048185 | BG3: =(847.509449948007-0)/3475.17933685976 -> 0.24387503 | BH3: =(848.871233227997-0)/3473.86808485756 -> 0.24435909 | BR3: =+IFERROR(AVERAGE(AT3:BQ3),"") -> 0.22506172 | BS3: =+IFERROR(VAR(AT3:BQ3),"") -> 0.00015609551 | BT3: =+IFERROR(STDEV(AT3:BQ3)*(1-$BS$1),"") -> 0.0062469095 | BU3: =+IF(OR(BT3="",OFFSET(AT3,0,MATCH($B$1,AT$2:BQ$2,0)-1)=""),"",IFERROR(IF(ABS(OFFSET(AT3,0,MATCH($B$1,AT$2:BQ$2,0)-1)-OFFSET(AT3,0,MATCH($B$1,AT$2:BQ$2,0)-2))>BT3,"N","µ"),"")) -> µ
C4: Tier 1 Risk-based Capital Ratio | D4: 0.125 | E4: 0.12 | F4: Capital Mgmt Group | H4: Y | L4: Y | P4: Y | Z4: YES | AC4: Monthly | AD4: RTS BSPR #0050 | AE4: Tier 1 capital divided by risk-weighted assets under baseline scenario. | AF4: Leslie Adames (threshold calibration) Comptrollership / Hector Ramos (monthly data) | AG4: ALTAIR system | AH4: Available on day 10th of each month. | AI4: Capital Policy | AJ4: Capital Policy from November 27, 2015 which was approved by the Board on December 8, 2015. Information is located in page 7, Table 3: 2015 SBC/BSPR Capital Expectations. the Planned capital hold was considered for the Amber trigger and the Business-as-usual was consideredfor the Red limit. | AL4: ALCO Risk Scorecard Quarterly Capital Trends | AM4: ALCO: December 2015 and January 2016 OK Quarterly: March. June and September 2015 OK | AO4: 0.152 | AP4: 0.1408 | AR4: 0.1582 | AS4: 0.1382 | AT4: =881.62/3824.4 -> 0.23052505 | AU4: =882.69/3827.05 -> 0.23064501 | AV4: =886.92/3744.04 -> 0.23688849 | AW4: =890.75234096/3767.184 -> 0.23645045 | AX4: =893.64630978/3827.715 -> 0.23346731 | AY4: =896.87773133/3854.980185 -> 0.2326543 | AZ4: =899.32698133/3832.377 -> 0.23466558 | BA4: =902.33900133/3790.394 -> 0.23805942 | BB4: =905.017492977999/3617.53992443135 -> 0.25017485 | BC4: =906.32/3601.15 -> 0.25167516 | BD4: =908.344820238001/3544.49459731878 -> 0.25626921 | BE4: =917.054273058005/3567.9148400942 -> 0.25702807 | BF4: =845.303335227995/3515.04 -> 0.24048185 | BG4: =847.509449948007/3475.17933685976 -> 0.24387503 | BH4: =848.871233227997/3473.86808485756 -> 0.24435909 | BR4: =+IFERROR(AVERAGE(AT4:BQ4),"") -> 0.24114792 | BS4: =+IFERROR(VAR(AT4:BQ4),"") -> 8.1242235e-05 | BT4: =+IFERROR(STDEV(AT4:BQ4)*(1-$BS$1),"") -> 0.0045067237 | BU4: =+IF(OR(BT4="",OFFSET(AT4,0,MATCH($B$1,AT$2:BQ$2,0)-1)=""),"",IFERROR(IF(ABS(OFFSET(AT4,0,MATCH($B$1,AT$2:BQ$2,0)-1)-OFFSET(AT4,0,MATCH($B$1,AT$2:BQ$2,0)-2))>BT4,"N","µ"),"")) -> µ
C5: Total Capital Ratio | D5: 0.145 | E5: 0.14 | F5: Capital Mgmt Group | H5: Y | L5: Y | P5: Y | T5: New from Group Dec-15 / Already in SHUSA RAS | U5: Tier I and Tier II capital based on BIS III regulations with phase in calendar | V5: Ensure alignment with Group definition | W5: Capital Team | X5: RAS Team | Z5: YES | AC5: Monthly | AD5: RTS BSPR #0051 | AE5: Total risk-based capital is the sum of tier 1 plus tier 2 capital under baseline scenario. Tier 1 capital consists of common shareholders equity, perpetual preferred shareholders equity with non-cumulative dividends, retained earnings, and minority interests in the equity accounts of consolidated subsidiaries. Tier 2 capital consists of subordinated debt, intermediate-term preferred stock, cumulative and long-term preferred stock, and a portion of a banks’ allowance for loan and lease losses. | AF5: Leslie Adames (threshold calibration) Comptrollership / Hector Ramos (monthly data) | AG5: ALTAIR system | AH5: Available on day 10th of each month. | AI5: Capital Policy | AJ5: Capital Policy from November 27, 2015 which was approved by the Board on December 8, 2015. Information is located in page 7, Table 3: 2015 SBC/BSPR Capital Expectations. the Planned capital hold was considered for the Amber trigger and the Business-as-usual was consideredfor the Red limit. | AL5: Quarterly Capital Trends | AM5: March 24.9% Different, June and September 2015 OK | AO5: 0.171 | AP5: 0.1608 | AR5: 0.1783 | AS5: 0.1583 | AT5: =929.78/3824.4 -> 0.24311787 | AU5: =930.9/3827.05 -> 0.24324218 | AV5: =934.97339448426/3744.03530307472 -> 0.24972345 | AW5: =938.21927945/3767.184 -> 0.24905056 | AX5: =941.88692978/3827.715 -> 0.24607029 | AY5: =945.44388633/3854.980185 -> 0.24525259 | AZ5: =947.63671533/3832.377 -> 0.24727127 | BA5: =950.13400133/3790.394 -> 0.25066893 | BB5: =950.69/3617.54 -> 0.26280013 | BC5: =951.83/3601.15 -> 0.26431279 | BD5: =953.157389234159/3544.49459731878 -> 0.26891207 | BE5: =962.149080349415/3567.9148400942 -> 0.26966705 | BF5: =889.729997481374/3515.04 -> 0.25312087 | BG5: =891.448349268745/3475.17933685976 -> 0.25651866 | BH5: =892.826478519448/3473.86808485756 -> 0.2570122 | BR5: =+IFERROR(AVERAGE(AT5:BQ5),"") -> 0.25378273 | BS5: =+IFERROR(VAR(AT5:BQ5),"") -> 8.1415052e-05 | BT5: =+IFERROR(STDEV(AT5:BQ5)*(1-$BS$1),"") -> 0.0045115145 | BU5: =+IF(OR(BT5="",OFFSET(AT5,0,MATCH($B$1,AT$2:BQ$2,0)-1)=""),"",IFERROR(IF(ABS(OFFSET(AT5,0,MATCH($B$1,AT$2:BQ$2,0)-1)-OFFSET(AT5,0,MATCH($B$1,AT$2:BQ$2,0)-2))>BT5,"N","µ"),"")) -> µ
C6: Tier 1 Leverage Ratio | D6: 0.1025 | E6: 0.0975 | F6: Capital Mgmt Group | H6: Y | L6: Y | P6: Y | Z6: YES | AC6: Monthly | AD6: RTS BSPR #0049 | AE6: The Tier 1 leverage ratio is calculated by dividing Tier 1 capital ratio by average total consolidated assets. | AF6: Leslie Adames (threshold calibration) Comptrollership / Hector Ramos (monthly data) | AG6: ALTAIR system | AH6: Available on day 10th of each month. | AI6: Capital Policy | AJ6: Capital Policy from November 27, 2015 which was approved by the Board on December 8, 2015. Information is located in page 7, Table 3: 2015 SBC/BSPR Capital Expectations. the Planned capital hold was considered for the Amber trigger and the Business-as-usual was consideredfor the Red limit. | AL6: ALCO Risk Scorecard Quarterly Capital Trends | AM6: ALCO: December 2015 and January 2016 OK Quarterly: March. June and September 2015 OK | AO6: 0.089 | AP6: 0.0812 | AR6: 0.108 | AS6: 0.088 | AT6: =881.62/5437.15 -> 0.16214745 | AU6: =882.69/5405.44 -> 0.1632966 | AV6: =886.92/5454.68 -> 0.16259799 | AW6: =890.75234096/5520.29404333 -> 0.16135958 | AX6: =893.64630978/5491.573 -> 0.16273048 | AY6: =896.87773133/5473.887961 -> 0.16384656 | AZ6: =899.32698133/5432.645 -> 0.16554128 | BA6: =902.33900133/5448.467 -> 0.16561337 | BB6: =905.017492977999/5443.264726678 -> 0.16626373 | BC6: =906.32/5398.96 -> 0.16786937 | BD6: =908.344820238001/5391.366186328 -> 0.16848138 | BE6: =917.054273058005/5379.26621439801 -> 0.17047944 | BF6: =845.303335227995/5317.39 -> 0.1589696 | BG6: =847.509449948007/5298.735556328 -> 0.1599456 | BH6: =848.871233227997/5303.055439328 -> 0.1600721 | BR6: =+IFERROR(AVERAGE(AT6:BQ6),"") -> 0.16394764 | BS6: =+IFERROR(VAR(AT6:BQ6),"") -> 1.1340756e-05 | BT6: =+IFERROR(STDEV(AT6:BQ6)*(1-$BS$1),"") -> 0.001683802 | BU6: =+IF(OR(BT6="",OFFSET(AT6,0,MATCH($B$1,AT$2:BQ$2,0)-1)=""),"",IFERROR(IF(ABS(OFFSET(AT6,0,MATCH($B$1,AT$2:BQ$2,0)-1)-OFFSET(AT6,0,MATCH($B$1,AT$2:BQ$2,0)-2))>BT6,"N","µ"),"")) -> µ
C7: Impairment to Pre-Provision Net Revenue (PPNR) (9Q CCAR stressed) | D7: $3,825MM | E7: $4,100 MM | F7: CCAR | H7: Y | L7: Y | P7: Y | T7: SIS is not subject to CCAR | Z7: YES | AC7: Annual | AE7: RAS Metrics Glossary: The projected 9Q cummulative increase in PPNR impairment between the CCAR BHC Stress and BHC Baseline scenarios and any available capital surplus under the CCAR BHC scenario. Material components include Total Revenue, Expenses due to Operational Risk and Expenses due to Residual Value Risk. | AF7: CCAR | AG7: CCAR | AH7: CCAR | AJ7: The methodology provided by SHUSA and Oliver Wyman is explained in the PDF file 20160426 CCAR-linked RAS methodology.pdf and the final calibration data is included in the PDF file 20160503 BSPR RAS Metrics.pdf. Please refer to slide 3. | AO7: CCAR | AP7: CCAR | AQ7: CCAR/OW | AR7: $296MM | AS7: $319MM | AT7: CCAR/OW | AU7: CCAR/OW | AV7: CCAR/OW | AW7: CCAR/OW | AX7: CCAR/OW | AY7: CCAR/OW | AZ7: CCAR/OW | BA7: CCAR/OW | BB7: CCAR/OW | BC7: CCAR/OW | BD7: CCAR/OW | BE7: CCAR/OW | BF7: CCAR/OW | BG7: CCAR/OW | BH7: 255 | BR7: =+IFERROR(AVERAGE(AT7:BQ7),"") -> 255 | BS7: =+IFERROR(VAR(AT7:BQ7),"") | BT7: =+IFERROR(STDEV(AT7:BQ7)*(1-$BS$1),"") | BU7: =+IF(OR(BT7="",OFFSET(AT7,0,MATCH($B$1,AT$2:BQ$2,0)-1)=""),"",IFERROR(IF(ABS(OFFSET(AT7,0,MATCH($B$1,AT$2:BQ$2,0)-1)-OFFSET(AT7,0,MATCH($B$1,AT$2:BQ$2,0)-2))>BT7,"N","µ"),""))
C8: Common Equity Tier 1 Ratio - stressed | P8: Y | Z8: YES | AC8: Annual | AF8: CCAR | AG8: CCAR | AH8: CCAR | AI8: Capital Policy | AJ8: The Capital Policy was used to calibrate , refer to page 7, Table 3. The Post-stress minimum was used to set the Red limit. To this the Stress absorption (1.71%) was added to calculate the Business-as-usual minimum, which was set as the Ambar trigger. This methodology was discussed and approved between the PR Capital Team and SHUSA's Capital Team. | AR8: =AS8+1.71% -> 0.1101 | AS8: 0.093 | AT8: CCAR/OW | AU8: CCAR/OW | AV8: CCAR/OW | AW8: CCAR/OW | AX8: CCAR/OW | AY8: CCAR/OW | AZ8: CCAR/OW | BA8: CCAR/OW | BB8: CCAR/OW | BC8: CCAR/OW | BD8: CCAR/OW | BE8: CCAR/OW | BF8: CCAR/OW | BG8: CCAR/OW | BH8: CCAR/OW | BR8: =+IFERROR(AVERAGE(AT8:BQ8),"") | BS8: =+IFERROR(VAR(AT8:BQ8),"") | BT8: =+IFERROR(STDEV(AT8:BQ8)*(1-$BS$1),"") | BU8: =+IF(OR(BT8="",OFFSET(AT8,0,MATCH($B$1,AT$2:BQ$2,0)-1)=""),"",IFERROR(IF(ABS(OFFSET(AT8,0,MATCH($B$1,AT$2:BQ$2,0)-1)-OFFSET(AT8,0,MATCH($B$1,AT$2:BQ$2,0)-2))>BT8,"N","µ"),""))
C9: Tier 1 Risk-based Capital Ratio - stressed | P9: Y | Z9: YES | AC9: Annual | AF9: CCAR | AG9: CCAR | AH9: CCAR | AI9: Capital Policy | AJ9: The Capital Policy was used to calibrate , refer to page 7, Table 3. The Post-stress minimum was used to set the Red limit. To this the Management Adjustment was added in order to set as the Ambar trigger (10.75% + 2.00%). This methodology was discussed and approved between the PR Capital Team and SHUSA's Capital Team. | AR9: =AS9+2% -> 0.1275 | AS9: 0.1075 | AT9: CCAR/OW | AU9: CCAR/OW | AV9: CCAR/OW | AW9: CCAR/OW | AX9: CCAR/OW | AY9: CCAR/OW | AZ9: CCAR/OW | BA9: CCAR/OW | BB9: CCAR/OW | BC9: CCAR/OW | BD9: CCAR/OW | BE9: CCAR/OW | BF9: CCAR/OW | BG9: CCAR/OW | BH9: CCAR/OW | BR9: =+IFERROR(AVERAGE(AT9:BQ9),"") | BS9: =+IFERROR(VAR(AT9:BQ9),"") | BT9: =+IFERROR(STDEV(AT9:BQ9)*(1-$BS$1),"") | BU9: =+IF(OR(BT9="",OFFSET(AT9,0,MATCH($B$1,AT$2:BQ$2,0)-1)=""),"",IFERROR(IF(ABS(OFFSET(AT9,0,MATCH($B$1,AT$2:BQ$2,0)-1)-OFFSET(AT9,0,MATCH($B$1,AT$2:BQ$2,0)-2))>BT9,"N","µ"),""))
C10: Total Capital Ratio - stressed | P10: Y | Z10: YES | AC10: Annual | AF10: CCAR | AG10: CCAR | AH10: CCAR | AI10: Capital Policy | AJ10: The Capital Policy was used to calibrate , refer to page 7, Table 3. The Post-stress minimum was used to set the Red limit. To this the Management Adjustment was added in order to set as the Ambar trigger (12.15% + 2.00%). This methodology was discussed and approved between the PR Capital Team and SHUSA's Capital Team. | AR10: =AS10+2% -> 0.1415 | AS10: 0.1215 | AT10: CCAR/OW | AU10: CCAR/OW | AV10: CCAR/OW | AW10: CCAR/OW | AX10: CCAR/OW | AY10: CCAR/OW | AZ10: CCAR/OW | BA10: CCAR/OW | BB10: CCAR/OW | BC10: CCAR/OW | BD10: CCAR/OW | BE10: CCAR/OW | BF10: CCAR/OW | BG10: CCAR/OW | BH10: CCAR/OW | BR10: =+IFERROR(AVERAGE(AT10:BQ10),"") | BS10: =+IFERROR(VAR(AT10:BQ10),"") | BT10: =+IFERROR(STDEV(AT10:BQ10)*(1-$BS$1),"") | BU10: =+IF(OR(BT10="",OFFSET(AT10,0,MATCH($B$1,AT$2:BQ$2,0)-1)=""),"",IFERROR(IF(ABS(OFFSET(AT10,0,MATCH($B$1,AT$2:BQ$2,0)-1)-OFFSET(AT10,0,MATCH($B$1,AT$2:BQ$2,0)-2))>BT10,"N","µ"),""))
C11: Tier 1 Leverage Ratio - stressed | P11: Y | Z11: YES | AC11: Annual | AF11: CCAR | AG11: CCAR | AH11: CCAR | AI11: Capital Policy | AJ11: The Capital Policy was used to calibrate , refer to page 7, Table 3. The Post-stress minimum was used to set the Red limit. To this the Management Adjustment was added in order to set as the Ambar trigger (6.80% + 2.00%). This methodology was discussed and approved between the PR Capital Team and SHUSA's Capital Team. | AR11: =AS11+2% -> 0.088 | AS11: 0.068 | AT11: CCAR/OW | AU11: CCAR/OW | AV11: CCAR/OW | AW11: CCAR/OW | AX11: CCAR/OW | AY11: CCAR/OW | AZ11: CCAR/OW | BA11: CCAR/OW | BB11: CCAR/OW | BC11: CCAR/OW | BD11: CCAR/OW | BE11: CCAR/OW | BF11: CCAR/OW | BG11: CCAR/OW | BH11: CCAR/OW | BR11: =+IFERROR(AVERAGE(AT11:BQ11),"") | BS11: =+IFERROR(VAR(AT11:BQ11),"") | BT11: =+IFERROR(STDEV(AT11:BQ11)*(1-$BS$1),"") | BU11: =+IF(OR(BT11="",OFFSET(AT11,0,MATCH($B$1,AT$2:BQ$2,0)-1)=""),"",IFERROR(IF(ABS(OFFSET(AT11,0,MATCH($B$1,AT$2:BQ$2,0)-1)-OFFSET(AT11,0,MATCH($B$1,AT$2:BQ$2,0)-2))>BT11,"N","µ"),""))
B12: Credit Risk (losses) | C12: Total Credit Losses (9Q stressed CCAR losses) | D12: CCAR | E12: CCAR | F12: CCAR | H12: Y | L12: Y | P12: Y | T12: Included in Loss in Stress calculation | Z12: YES | AC12: Annual | AE12: RAS Metrics Glossary: 9Q stressed cummulativw credit losses and any available capital surplus under the CCAR BHC Stress scenario | AF12: CCAR (threshold calibration) | AJ12: The methodology provided by SHUSA and Oliver Wyman is explained in the PDF file 20160426 CCAR-linked RAS methodology.pdf and the final calibration data is included in the PDF file 20160503 BSPR RAS Metrics.pdf. Please refer to slide 3. | AO12: CCAR | AP12: CCAR | AQ12: CCAR/OW | AR12: $315MM | AS12: $340MM | AT12: CCAR/OW | AU12: CCAR/OW | AV12: CCAR/OW | AW12: CCAR/OW | AX12: CCAR/OW | AY12: CCAR/OW | AZ12: CCAR/OW | BA12: CCAR/OW | BB12: CCAR/OW | BC12: CCAR/OW | BD12: CCAR/OW | BE12: CCAR/OW | BF12: CCAR/OW | BG12: CCAR/OW | BH12: 239 | BR12: =+IFERROR(AVERAGE(AT12:BQ12),"") -> 239 | BS12: =+IFERROR(VAR(AT12:BQ12),"") | BT12: =+IFERROR(STDEV(AT12:BQ12)*(1-$BS$1),"") | BU12: =+IF(OR(BT12="",OFFSET(AT12,0,MATCH($B$1,AT$2:BQ$2,0)-1)=""),"",IFERROR(IF(ABS(OFFSET(AT12,0,MATCH($B$1,AT$2:BQ$2,0)-1)-OFFSET(AT12,0,MATCH($B$1,AT$2:BQ$2,0)-2))>BT12,"N","µ"),""))
C13: NCO PR Mortgages | D13: New 2016 | E13: New 2016 | F13: CCAR | H13: N | L13: Y | P13: Y | Y13: -Please confirm if the Material Portfolios are to be divided between Total Outstanding Portfolio or Total Outstanding of the Material Portfolios. [SA]: Total outstanding of the material portfolios -Are we supposed to use the methodology that SBNA uses included in the RAS Metrics Glossary? (Most recent month's total NCO multiplied by 12 and divided by the Total outstanding balances) [SA]: No - changing to rolling 12-month NCO/rolling 12-month outstanding balance BSPR - shouldn't the denominator of the metric be the average of the rolling 12-month outstanding balance (such as SCUSA) -In order to calculate the annualized amount should we multiply the Most recent month's NCO by 12 or by (number of month/12)? [SA]: As above -In order to be aligned with the Local Credit Trends Report which considers 12 month NCO divided by Average Portfolio, could we consider the local monitoring metric for the RAS? [SA]: As above - we are discussing with Oliver Wyman the possibility of adding change in provisions over 12-mo to the metric | Z13: YES | AC13: Monthly | AE13: NUMERATOR: 12M NCO - Mortgage Portfolio divided by DENOMINATOR: KPI Total 12 Average Portfolio - Mortgage Portfolio | AF13: CCAR (threshold calibration) Risk MI / Rafael Martínez (monthly data) | AG13: CARMOSA PRODUCTO 1 = HIPOTECAS | AH13: day 10th of each month depending on Accounting reconciliation | AJ13: The methodology provided by SHUSA and Oliver Wyman is explained in the PDF file 20160426 CCAR-linked RAS methodology.pdf and the final calibration data is included in the PDF file 20160503 BSPR RAS Metrics.pdf. Please refer to slide 2. | AK13: =20060117.7740878/1278275057.73207 -> 0.015693115 | AL13: Report: Credit Trends as reported by Portfolio Management | AM13: 2015 Q1: 1.5% OK Q2: 1.5% Q3: 1.7% | AQ13: OW | AR13: 0.017 | AS13: 0.019 | AT13: =21001300.1/1443574666.66667 -> 0.014548122 | AU13: =21353526.28/1438131583.33333 -> 0.014848103 | AV13: =20655365.18/1432882916.66667 -> 0.01441525 | AW13: =19656496.58/1427362916.66667 -> 0.013771197 | AX13: =19571143.83/1421325083.33333 -> 0.013769646 | AY13: =20402700.95/1414776583.33333 -> 0.014421147 | AZ13: =21304105.16/1408744750 -> 0.015122757 | BA13: =20565865.8/1401857916.66667 -> 0.014670435 | BB13: =20836772.33/1394724416.66667 -> 0.014939706 | BC13: =21333587.2/1387280916.66667 -> 0.015377986 | BD13: =21717263.97/1379486750 -> 0.015743003 | BE13: =22524389.6/1371939166.66667 -> 0.016417922 | BF13: =22407272.63/1364507916.66667 -> 0.016421504 | BG13: =22227209.44/1356836416.66667 -> 0.016381643 | BH13: =22333149.36/1348510250 -> 0.016561349 | BR13: =+IFERROR(AVERAGE(AT13:BQ13),"") -> 0.015160651 | BS13: =+IFERROR(VAR(AT13:BQ13),"") -> 9.1007371e-07 | BT13: =+IFERROR(STDEV(AT13:BQ13)*(1-$BS$1),"") -> 0.00047698892 | BU13: =+IF(OR(BT13="",OFFSET(AT13,0,MATCH($B$1,AT$2:BQ$2,0)-1)=""),"",IFERROR(IF(ABS(OFFSET(AT13,0,MATCH($B$1,AT$2:BQ$2,0)-1)-OFFSET(AT13,0,MATCH($B$1,AT$2:BQ$2,0)-2))>BT13,"N","µ"),"")) -> µ | BV13: Ask Paola if in the Credit Trends Portfolio management (12-mo Net Ch Offs/AVG Portfolio) the methodology considers Exposure or Outstanding. And is this the result of the last month or an avrage of the Quarter. Here we use outstanding.
C14: NCO PR Commercial Banking | D14: New 2016 | E14: New 2016 | F14: CCAR | H14: N | L14: Y | P14: Y | Z14: YES | AC14: Monthly | AE14: NUMERATOR: 12M NCO - Commercial Portfolio (includes: COMMERCIAL, CONSTRUCTION, OVERDRAFTS, RCS COMMERCIAL) divided by DENOMINATOR: KPI Total 12 Average Portfolio - Commercial Portfolio (includes: COMMERCIAL, CONSTRUCTION, OVERDRAFTS, RCS COMMERCIAL) | AF14: CCAR (threshold calibration) Risk MI / Rafael Martínez (monthly data) | AG14: CARMOSA: PRODUCTO 1 = COMMERCIAL + CONSTRUCTION | AH14: day 10th of each month depending on Accounting reconciliation | AJ14: The methodology provided by SHUSA and Oliver Wyman is explained in the PDF file 20160426 CCAR-linked RAS methodology.pdf and the final calibration data is included in the PDF file 20160503 BSPR RAS Metrics.pdf. Please refer to slide 2. | AK14: =9841038.63514543/1826186084.21375 -> 0.0053888477 | AL14: Report: Credit Trends as reported by Portfolio Management | AM14: ? | AQ14: OW | AR14: 0.005 | AS14: 0.006 | AT14: =5192599.46/2738561858.195 -> 0.0018961045 | AU14: =5439071.96/2656696274.86167 -> 0.0020473067 | AV14: =4684676.98/2581624024.86167 -> 0.001814624 | AW14: =4907338.01/2517439774.86167 -> 0.0019493368 | AX14: =4674975.06/2473308941.52833 -> 0.0018901703 | AY14: =5512214.9/2441755441.52833 -> 0.0022574803 | AZ14: =5612158.96/2408152024.86167 -> 0.0023304837 | BA14: =6126246.17/2377974691.52833 -> 0.0025762453 | BB14: =5290289.24/2338461139.77833 -> 0.0022622951 | BC14: =5514186.35/2301265531.58333 -> 0.0023961539 | BD14: =6765650.66/2267714864.91667 -> 0.0029834662 | BE14: =5699008.93/2247575364.91667 -> 0.0025356253 | BF14: =5988769.71/2234301114.91667 -> 0.0026803772 | BG14: =6935964.59/2219931531.58333 -> 0.0031244047 | BH14: =7429278.09/2206237781.58333 -> 0.0033673968 | BR14: =+IFERROR(AVERAGE(AT14:BQ14),"") -> 0.0024074314 | BS14: =+IFERROR(VAR(AT14:BQ14),"") -> 2.254575e-07 | BT14: =+IFERROR(STDEV(AT14:BQ14)*(1-$BS$1),"") -> 0.00023741183 | BU14: =+IF(OR(BT14="",OFFSET(AT14,0,MATCH($B$1,AT$2:BQ$2,0)-1)=""),"",IFERROR(IF(ABS(OFFSET(AT14,0,MATCH($B$1,AT$2:BQ$2,0)-1)-OFFSET(AT14,0,MATCH($B$1,AT$2:BQ$2,0)-2))>BT14,"N","µ"),"")) -> N | BV14: Ask Paola what is the equivalent metric reported in the Credit Trands report for this.
C15: NCO PR Personal Loans | D15: New 2016 | E15: New 2016 | F15: CCAR | H15: N | L15: Y | P15: Y | Z15: YES | AC15: Monthly | AE15: NUMERATOR: 12M NCO - Personal Loans Portfolio divided by DENOMINATOR: KPI Total 12 Average Portfolio - Personal Loans Portfolio | AF15: CCAR (threshold calibration) Risk MI / Rafael Martínez (monthly data) | AG15: CARMOSA PRODUCTO 1 = CONSUMO | AH15: day 10th of each month depending on Accounting reconciliation | AJ15: The methodology provided by SHUSA and Oliver Wyman is explained in the PDF file 20160426 CCAR-linked RAS methodology.pdf and the final calibration data is included in the PDF file 20160503 BSPR RAS Metrics.pdf. Please refer to slide 2. | AK15: =12885320.0264068/243323603.487228 -> 0.052955487 | AL15: Report: Credit Trends as reported by Portfolio Management | AM15: 2015 Q1: 5.0% Q2: 5.1% Q3: 5.1% | AQ15: OW | AR15: 0.054 | AS15: 0.06 | AT15: =11900742.26/267267083.333333 -> 0.044527527 | AU15: =12011720.34/267490500 -> 0.044905222 | AV15: =12276309.94/267731166.666667 -> 0.045853122 | AW15: =12451267.6/267956333.333333 -> 0.046467525 | AX15: =12578459.62/268305083.333333 -> 0.046881183 | AY15: =12310548.87/268616750 -> 0.045829416 | AZ15: =12178575.37/268901000 -> 0.045290183 | BA15: =12114629.17/268876500 -> 0.045056482 | BB15: =11983748.41/268800916.666667 -> 0.044582245 | BC15: =11844779.7/268531750 -> 0.04410942 | BD15: =11829246.07/268045916.666667 -> 0.044131417 | BE15: =12110431.5/267291798.845 -> 0.045307905 | BF15: =11860979.58/266336382.178333 -> 0.044533832 | BG15: =11903712.79/265031215.511667 -> 0.04491438 | BH15: =11834996.41/263559048.845 -> 0.044904535 | BR15: =+IFERROR(AVERAGE(AT15:BQ15),"") -> 0.04515296 | BS15: =+IFERROR(VAR(AT15:BQ15),"") -> 6.5196707e-07 | BT15: =+IFERROR(STDEV(AT15:BQ15)*(1-$BS$1),"") -> 0.00040372239 | BU15: =+IF(OR(BT15="",OFFSET(AT15,0,MATCH($B$1,AT$2:BQ$2,0)-1)=""),"",IFERROR(IF(ABS(OFFSET(AT15,0,MATCH($B$1,AT$2:BQ$2,0)-1)-OFFSET(AT15,0,MATCH($B$1,AT$2:BQ$2,0)-2))>BT15,"N","µ"),"")) -> µ | BV15: Ask Paola if Net Write Off 12m (%) from the Credit Trends report is the equivalent. If so, what is the methodology? Esposure or Outstanding? Can we compare against this metric?
C16: NCO PR Credit Cards | D16: New 2016 | E16: New 2016 | F16: CCAR | H16: N | L16: Y | P16: Y | Z16: YES | AC16: Monthly | AE16: NUMERATOR: 12M NCO - Credit Cards Portfolio divided by DENOMINATOR: KPI Total 12 Average Portfolio - Credit Cards Portfolio | AF16: CCAR (threshold calibration) Risk MI / Rafael Martínez (monthly data) | AG16: CARMOSA PRODUCTO 1 = TARJETAS | AH16: day 10th of each month depending on Accounting reconciliation | AJ16: The methodology provided by SHUSA and Oliver Wyman is explained in the PDF file 20160426 CCAR-linked RAS methodology.pdf and the final calibration data is included in the PDF file 20160503 BSPR RAS Metrics.pdf. Please refer to slide 2. | AK16: =15036935.4473544/238217331.128349 -> 0.06312276 | AL16: Report: Credit Trends as reported by Portfolio Management | AM16: 2015 Q1: 6.8% Q2: 6.8% Q3: 6.8% | AQ16: OW | AR16: 0.064 | AS16: 0.074 | AT16: =14750662.42/236322583.333333 -> 0.06241749 | AU16: =14710669.36/237218500 -> 0.062013162 | AV16: =14881019.21/237856166.666667 -> 0.0625631 | AW16: =15070394.47/238445083.333333 -> 0.06320279 | AX16: =15373030.78/238897916.666667 -> 0.06434979 | AY16: =15201929.06/239192000 -> 0.063555341 | AZ16: =15193929.08/239308166.666667 -> 0.06349106 | BA16: =14831436.24/239452916.666667 -> 0.061938841 | BB16: =15127496.74/239363479.833333 -> 0.06319885 | BC16: =14987897.0205/239135313.166667 -> 0.062675382 | BD16: =14795608.4407/238787896.5 -> 0.0619613 | BE16: =15175513.0107/238161809.885 -> 0.063719339 | BF16: =15236139.3807/237437893.218333 -> 0.064168946 | BG16: =15022513.4007/236594476.551667 -> 0.063494776 | BH16: =14667857.8107/235718559.885 -> 0.062226147 | BR16: =+IFERROR(AVERAGE(AT16:BQ16),"") -> 0.062998421 | BS16: =+IFERROR(VAR(AT16:BQ16),"") -> 6.4242996e-07 | BT16: =+IFERROR(STDEV(AT16:BQ16)*(1-$BS$1),"") -> 0.00040075864 | BU16: =+IF(OR(BT16="",OFFSET(AT16,0,MATCH($B$1,AT$2:BQ$2,0)-1)=""),"",IFERROR(IF(ABS(OFFSET(AT16,0,MATCH($B$1,AT$2:BQ$2,0)-1)-OFFSET(AT16,0,MATCH($B$1,AT$2:BQ$2,0)-2))>BT16,"N","µ"),"")) -> N | BV16: Ask Paola if Net Write Off 12m (%) from the Credit Trends report is the equivalent. If so, what is the methodology? Esposure or Outstanding? Can we compare against this metric?
C17: NCO PR TOTAL | P17: Y | Z17: YES | AC17: Monthly | AD17: RSC BSPR #0089 | AE17: It is calculated as twelve month rolling Net Charge Offs (NCO) (i.e., charge off’s less recoveries, excluding the sale of charge off portfolio) divided by average loans portfolio. NCO are the total loans and leases removed from the balance sheet due to their uncollectability minus amounts recovered on loans and leases previously charged-off. NUMERATOR: 12M NCO PR Total divided by DENOMINATOR: KPI Total 12 Average Portfolio - Total | AF17: CCAR (threshold calibration) Risk MI / Rafael Martínez (monthly data) | AG17: Database 1001 | AH17: day 5th of each month | AI17: Budget | AJ17: The methodology provided by SHUSA and Oliver Wyman is explained in the PDF file 20160426 CCAR-linked RAS methodology.pdf and the final calibration data is included in the PDF file 20160503 BSPR RAS Metrics.pdf. Please refer to slide 2. | AK17: 0.016 | AO17: 0.014 | AP17: 0.016 | AQ17: OW | AR17: 0.017 | AS17: 0.018 | AT17: =52845304.24/4685726191.52833 -> 0.011277933 | AU17: =53514987.94/4599536858.195 -> 0.011634864 | AV17: =52497371.31/4520094274.86167 -> 0.01161422 | AW17: =52085496.66/4451204108.195 -> 0.01170144 | AX17: =52197609.29/4401837024.86167 -> 0.011858142 | AY17: =53427393.78/4364340774.86167 -> 0.012241802 | AZ17: =54288768.57/4325105941.52833 -> 0.012552009 | BA17: =53638177.38/4288162024.86167 -> 0.012508431 | BB17: =53238306.72/4241349952.945 -> 0.012552208 | BC17: =53680450.2705/4196213511.41667 -> 0.012792593 | BD17: =55107769.1407/4154035428.08333 -> 0.013266081 | BE17: =55509343.0407/4124968140.31333 -> 0.013456914 | BF17: 0.014 | BG17: =56.0894002207/4078.39359031583 -> 0.013752817 | BH17: =56265281.6707/4054025640.31333 -> 0.013878867 | BR17: =+IFERROR(AVERAGE(AT17:BQ17),"") -> 0.012605888 | BS17: =+IFERROR(VAR(AT17:BQ17),"") -> 8.0636975e-07 | BT17: =+IFERROR(STDEV(AT17:BQ17)*(1-$BS$1),"") -> 0.00044899046 | BU17: =+IF(OR(BT17="",OFFSET(AT17,0,MATCH($B$1,AT$2:BQ$2,0)-1)=""),"",IFERROR(IF(ABS(OFFSET(AT17,0,MATCH($B$1,AT$2:BQ$2,0)-1)-OFFSET(AT17,0,MATCH($B$1,AT$2:BQ$2,0)-2))>BT17,"N","µ"),"")) -> µ | BV17: Cristina - revisar presupuesto e incluir en columna 'Budget' y resultado de Enero/2016 debe dar igual que RTS. Los niveles deben dar igual a lo presentado por Blanca en el BSPR RSC Review
C18: 60+ PR Mortgages | D18: New 2016 | E18: New 2016 | F18: CCAR | H18: N | L18: Y | P18: Y | Y18: Please confirm if the Material Portfolios are to be divided between Total Outstanding Portfolio or Total Outstanding of the Material Portfolios. [SA]: Outstanding of material portfolios | Z18: YES | AC18: Monthly | AE18: NUMERATOR: 60+ days past due Mortgage Portfolio divided by DENOMINATOR: Total Outstanding Balance of Mortgage Portfolio | AF18: CCAR (threshold calibration) Risk MI / Rafael Martínez (monthly data) | AG18: TABLA 1001 = QUERY 0700 | AH18: day 10th of each month depending on Accounting reconciliation | AJ18: The methodology provided by SHUSA and Oliver Wyman is explained in the PDF file 20160426 CCAR-linked RAS methodology.pdf and the final calibration data is included in the PDF file 20160503 BSPR RAS Metrics.pdf. Please refer to slide 4. | AK18: =126.249963851156/1297.64620955215 -> 0.097291514 | AQ18: OW | AR18: 0.106 | AS18: 0.12 | AT18: =135528625.18/1410797000 -> 0.096065292 | AU18: =132504856.2/1403633000 -> 0.094401354 | AV18: =132409704.94/1404930000 -> 0.094246478 | AW18: =134792740.47/1398378000 -> 0.096392206 | AX18: =133821996.92/1386142000 -> 0.096542776 | AY18: =132546435.15/1375241000 -> 0.096380515 | AZ18: =135227944.09/1376171000 -> 0.098263911 | BA18: =132998905.85/1357761000 -> 0.097954578 | BB18: =129996579.14/1348720000 -> 0.09638515 | BC18: =128809994.53/1341648000 -> 0.096008785 | BD18: =132068871.11/1332006000 -> 0.099150358 | BE18: =127596797.49/1327843000 -> 0.096093286 | BF18: =127308962.19/1321622000 -> 0.096327817 | BG18: =123254702.18/1311575000 -> 0.093974574 | BH18: =110803287.35/1305016000 -> 0.084905693 | BR18: =+IFERROR(AVERAGE(AT18:BQ18),"") -> 0.095539518 | BS18: =+IFERROR(VAR(AT18:BQ18),"") -> 1.0669168e-05 | BT18: =+IFERROR(STDEV(AT18:BQ18)*(1-$BS$1),"") -> 0.0016331846 | BU18: =+IF(OR(BT18="",OFFSET(AT18,0,MATCH($B$1,AT$2:BQ$2,0)-1)=""),"",IFERROR(IF(ABS(OFFSET(AT18,0,MATCH($B$1,AT$2:BQ$2,0)-1)-OFFSET(AT18,0,MATCH($B$1,AT$2:BQ$2,0)-2))>BT18,"N","µ"),"")) -> N | BV18: OK Confirmed 3/10/2016
C19: 60+ PR Personal Loans | D19: New 2016 | E19: New 2016 | F19: CCAR | H19: N | L19: Y | P19: Y | Z19: YES | AC19: Monthly | AE19: NUMERATOR: 60+ days past due Personal Loans Portfolio divided by DENOMINATOR: Total Outstanding Balance of Personal Loans Portfolio | AF19: CCAR (threshold calibration) Risk MI / Rafael Martínez (monthly data) | AG19: TABLA 1001 = QUERY 0700 | AH19: day 10th of each month depending on Accounting reconciliation | AJ19: The methodology provided by SHUSA and Oliver Wyman is explained in the PDF file 20160426 CCAR-linked RAS methodology.pdf and the final calibration data is included in the PDF file 20160503 BSPR RAS Metrics.pdf. Please refer to slide 4. | AK19: =2.92728882971842/243.309059327228 -> 0.012031154 | AQ19: OW | AR19: 0.015 | AS19: 0.017 | AT19: =3281975.77/267760000 -> 0.012257155 | AU19: =3368994.58/268881000 -> 0.012529686 | AV19: =3184008.85/268031000 -> 0.011879256 | AW19: =3106624.74/269291000 -> 0.011536311 | AX19: =3069150.7/270174000 -> 0.011359904 | AY19: =3106639.83/270540000 -> 0.011483107 | AZ19: =3367879.94/269777000 -> 0.01248394 | BA19: =3694288.27/268404000 -> 0.013763909 | BB19: =3185553.77/267138000 -> 0.01192475 | BC19: =3088628.47/265938000 -> 0.011614092 | BD19: =3248285.83/262427000 -> 0.012377864 | BE19: =3433970.14/259140586.14 -> 0.013251379 | BF19: =3569446.67/256295000 -> 0.013927102 | BG19: =3735624.25/253219000 -> 0.014752543 | BH19: =3739986.58/250365000 -> 0.014938137 | BR19: =+IFERROR(AVERAGE(AT19:BQ19),"") -> 0.012671942 | BS19: =+IFERROR(VAR(AT19:BQ19),"") -> 1.4008815e-06 | BT19: =+IFERROR(STDEV(AT19:BQ19)*(1-$BS$1),"") -> 0.0005917942 | BU19: =+IF(OR(BT19="",OFFSET(AT19,0,MATCH($B$1,AT$2:BQ$2,0)-1)=""),"",IFERROR(IF(ABS(OFFSET(AT19,0,MATCH($B$1,AT$2:BQ$2,0)-1)-OFFSET(AT19,0,MATCH($B$1,AT$2:BQ$2,0)-2))>BT19,"N","µ"),"")) -> N | BV19: OK Confirmed 3/10/2016
C20: 60+ PR Credit Cards | D20: New 2016 | E20: New 2016 | F20: CCAR | H20: N | L20: Y | P20: Y | Z20: YES | AC20: Monthly | AE20: NUMERATOR: 60+ days past due Credit Cards Portfolio divided by DENOMINATOR: Total Outstanding Balance of Credit Cards Portfolio | AF20: CCAR (threshold calibration) Risk MI / Rafael Martínez (monthly data) | AG20: TABLA 1001 = QUERY 0700 | AH20: day 10th of each month depending on Accounting reconciliation | AJ20: The methodology provided by SHUSA and Oliver Wyman is explained in the PDF file 20160426 CCAR-linked RAS methodology.pdf and the final calibration data is included in the PDF file 20160503 BSPR RAS Metrics.pdf. Please refer to slide 4. | AK20: =11.9094024173571/237.970414168349 -> 0.050045727 | AQ20: OW | AR20: 0.023 | AS20: 0.026 | AT20: =6124188.16/241348000 -> 0.025374928 | AU20: =6154544.16/240428000 -> 0.025598284 | AV20: =5586644.79/237669000 -> 0.023505989 | AW20: =5088717.14/239372000 -> 0.021258615 | AX20: =5063346.41/239138000 -> 0.021173324 | AY20: =4864548.23/239704000 -> 0.02029398 | AZ20: =4915238.59/238959000 -> 0.02056938 | BA20: =5214333.41/239065000 -> 0.021811363 | BB20: =5031679.62/237211758 -> 0.021211763 | BC20: =5120391.01/235516000 -> 0.02174116 | BD20: =5442722.97/236229000 -> 0.023040029 | BE20: =5358917.61/233301960.62 -> 0.022969878 | BF20: =5495221.35/232661000 -> 0.023619005 | BG20: =5572586.62/230307000 -> 0.024196341 | BH20: =5380531.07/227158000 -> 0.023686294 | BR20: =+IFERROR(AVERAGE(AT20:BQ20),"") -> 0.022670022 | BS20: =+IFERROR(VAR(AT20:BQ20),"") -> 2.7926401e-06 | BT20: =+IFERROR(STDEV(AT20:BQ20)*(1-$BS$1),"") -> 0.00083555971 | BU20: =+IF(OR(BT20="",OFFSET(AT20,0,MATCH($B$1,AT$2:BQ$2,0)-1)=""),"",IFERROR(IF(ABS(OFFSET(AT20,0,MATCH($B$1,AT$2:BQ$2,0)-1)-OFFSET(AT20,0,MATCH($B$1,AT$2:BQ$2,0)-2))>BT20,"N","µ"),"")) -> µ | BV20: OK Confirmed 3/10/2016
C21: 60+ PR Commercial Banking | P21: Y | Z21: YES | AC21: Monthly | AE21: NUMERATOR: 60+ days past due Commercial Portfolio divided by DENOMINATOR: Total Outstanding Balance of Commercial Portfolio | AF21: CCAR (threshold calibration) Risk MI / Rafael Martínez (monthly data) | AG21: TABLA 1001 = QUERY 0700 | AH21: day 10th of each month depending on Accounting reconciliation | AJ21: The methodology provided by SHUSA and Oliver Wyman is explained in the PDF file 20160426 CCAR-linked RAS methodology.pdf and the final calibration data is included in the PDF file 20160503 BSPR RAS Metrics.pdf. Please refer to slide 4. | AQ21: OW | AR21: 0.042 | AS21: 0.05 | AT21: =38054535.65/2271638000 -> 0.016752025 | AU21: =36338797.18/2255504000 -> 0.016111165 | AV21: =34670646.47/2261434000 -> 0.015331266 | AW21: =34766026.29/2274490000 -> 0.015285196 | AX21: =34357712.53/2332033000 -> 0.014732944 | AY21: =33551187.93/2369839000 -> 0.014157581 | AZ21: =51090472.45/2347412000 -> 0.021764595 | BA21: =42035363.2/2316949000 -> 0.01814255 | BB21: =45809367.39/2162084379 -> 0.021187595 | BC21: =42045568.68/2141807000 -> 0.019630886 | BD21: =51483463.03/2103880000 -> 0.024470722 | BE21: =45016281.34/2133834000 -> 0.021096431 | BF21: =42846996.51/2112347000 -> 0.020284071 | BG21: =43308674.27/2083069000 -> 0.020790802 | BH21: =43802749.65/2097109000 -> 0.020887207 | BR21: =+IFERROR(AVERAGE(AT21:BQ21),"") -> 0.018708336 | BS21: =+IFERROR(VAR(AT21:BQ21),"") -> 9.810134e-06 | BT21: =+IFERROR(STDEV(AT21:BQ21)*(1-$BS$1),"") -> 0.0015660567 | BU21: =+IF(OR(BT21="",OFFSET(AT21,0,MATCH($B$1,AT$2:BQ$2,0)-1)=""),"",IFERROR(IF(ABS(OFFSET(AT21,0,MATCH($B$1,AT$2:BQ$2,0)-1)-OFFSET(AT21,0,MATCH($B$1,AT$2:BQ$2,0)-2))>BT21,"N","µ"),"")) -> µ | BV21: OK Confirmed 3/10/2016
C22: 60+ PR TOTAL | P22: Y | Y22: Included a new 60+ Total Metric to monitor NCOs at a Consolidadted Bank level Portfolio Management: 60+ Total PR: sugiero eliminarlo pues en realidad no hay un gestor identificado en el Banco que observe esta cifra agregada. Aún más, las estrategias para los productos/segmentos son tan distintas que se recogen en PEC’s distintos administrados por grupos ejecutivos distintos. | Z22: YES | AE22: NUMERATOR: 60+ Total Portfolio divided by DENOMINATOR: Total Portfolio % | AF22: CCAR (threshold calibration) Risk MI / Rafael Martínez (monthly data) | AG22: TABLA 1001 = QUERY 0700 | AH22: day 10th of each month depending on Accounting reconciliation | AJ22: The methodology provided by SHUSA and Oliver Wyman is explained in the PDF file 20160426 CCAR-linked RAS methodology.pdf and the final calibration data is included in the PDF file 20160503 BSPR RAS Metrics.pdf. Please refer to slide 4. | AQ22: OW | AR22: 0.061 | AS22: 0.07 | AT22: =182989324.76/4191543000 -> 0.043656793 | AU22: =178367192.12/4168446000 -> 0.042789853 | AV22: =175851005.05/4172064000 -> 0.042149642 | AW22: =177754108.64/4181531000 -> 0.042509337 | AX22: =176312206.56/4227487000 -> 0.04170615 | AY22: =174068811.14/4255324000 -> 0.040906124 | AZ22: =194601535.07/4232319000 -> 0.045979884 | BA22: =183942890.73/4182179000 -> 0.043982549 | BB22: =184023179.92/4015154137 -> 0.045832158 | BC22: =179064582.69/3984909000 -> 0.044935677 | BD22: =192243342.94/3934542000 -> 0.048860412 | BE22: =181405966.58/3954119546.76 -> 0.045877714 | BF22: =179220626.72/3922925000 -> 0.045685458 | BG22: =175871587.32/3878170000 -> 0.045349118 | BH22: =163726554.65/3879648000 -> 0.042201394 | BR22: =+IFERROR(AVERAGE(AT22:BQ22),"") -> 0.044161484 | BS22: =+IFERROR(VAR(AT22:BQ22),"") -> 4.6334737e-06 | BT22: =+IFERROR(STDEV(AT22:BQ22)*(1-$BS$1),"") -> 0.0010762753 | BU22: =+IF(OR(BT22="",OFFSET(AT22,0,MATCH($B$1,AR$2:BO$2,0)-1)=""),"",IFERROR(IF(ABS(OFFSET(AT22,0,MATCH($B$1,AR$2:BO$2,0)-1)-OFFSET(AT22,0,MATCH($B$1,AR$2:BO$2,0)-2))>BT22,"N","µ"),"")) | BV22: Used 'Concentration To One Obligor Without Guarantee' | BY22: Comparamos
B23: Credit risk (concentration) | C23: Single Obligor (Corp. and IFIs) Exposure Without Guarantee | D23: N/A | E23: $500 MM | F23: Solvency | H23: Y | L23: Y | P23: Y | Z23: YES | AA23: Used 'Concentration To One Obligor Without Guarantee' RTS metric | AC23: Monthly | AD23: RTS BSPR 0020 | AE23: Used 'Concentration To One Obligor Without Guarantee' Total exposure of largest one obligor without guarantee (excluding U.S. and P.R. Government authorities, agencies, dependencies and municipalities’ loans) is compared with legal lending limit permitted by the Banking Law of Puerto Rico. The maximum loan limit to one obligor permitted by the Banking Law of Puerto Rico is up to 15% of the 50% of the bank’s undistributed earnings. To identify the highest obligor without guarantee in the Database 1001 BSPR, it shoud be filtered as follows: 1- Bank column select “004” (BSPR bank) 2- Product column select “05” (Commercial Risk) 3- Group name column exclude “Abengoa” (Abengoa group is the highest exposure however only $25MM is without guarantee). 4- Segment Column exclude “Institucional Público” (U.S and P R Government authorities, agencies, dependencies and municipalities’ loans) 5- Guarantee group select “Sin Garantía” The balance used is “Riesgo del cliente”, after filters have been applied, it should be sorted in order to identify the highest balance. The legal lending limit is calculated by Contropllership Unit in a quarterly basis and reported to ERM officers. | AF23: Risk MI / Rafael Martínez | AG23: TABLA 1001 | AH23: day 10th of each month depending on Accounting reconciliation | AJ23: Considered the Legal Lending Limit as of 3/31/2016 ($69.6MM). The 20% deviation from the Red (Limit) to the Green level represents the buffer permitted by the BOD to the Senior Management to manage the risks without risking the Bank’s capital. Per the Capital Stress Test (CCAR), there is ~20% distance from the baseline to the adverse scenario (stressed) while still maintaining the capital levels above the limits required by the regulator. That ~20% deviation is used from the Red (Limit) to the Green level in the RAS thus integrating the Capital Stress Test (CCAR) into the RAS. | AQ23: $55.7MM | AR23: $55.8MM | AS23: $69.6MM | AT23: 37.927291 | AU23: 37.927291 | AV23: 37.927202 | AW23: 37.779458 | AX23: 37.779458 | AY23: 36.03334 | AZ23: 36.033226 | BA23: 36.033226 | BB23: 36.033132 | BC23: 35.588046 | BD23: 35.588046 | BE23: 40 | BF23: 26 | BG23: 26 | BH23: 26 | BR23: =+IFERROR(AVERAGE(AT23:BQ23),"") -> 34.843314 | BS23: =+IFERROR(VAR(AT23:BQ23),"") -> 22.410783 | BT23: =+IFERROR(STDEV(AT24:BQ24)*(1-$BS$1),"") -> 32.31606 | BU23: =+IF(OR(BT23="",OFFSET(AT24,0,MATCH($B$1,AT$2:BQ$2,0)-1)=""),"",IFERROR(IF(ABS(OFFSET(AT24,0,MATCH($B$1,AT$2:BQ$2,0)-1)-OFFSET(AT24,0,MATCH($B$1,AT$2:BQ$2,0)-2))>BT23,"N","µ"),"")) -> µ | BW23: Used to be Single obligor exposure, included (Corp. and IFIs) to the name
C24: Top 20 Corporates Exposure | D24: $7.0B | E24: $8.0 B | F24: Solvency | H24: Y | L24: Y | P24: Y | Y24: 4/28/2016 Excludes Public Sector | Z24: YES | AC24: Monthly | AE24: Top 20 Total Exposure. Segment Column exclude “Institucional Público” (U.S and P R Government authorities, agencies, dependencies and municipalities’ loans) | AF24: Risk MI / Rafael Martínez | AG24: TABLA 1001 | AH24: day 10th of each month depending on Accounting reconciliation | AJ24: Thresholds defined per Historical Data: The the Green level is defined considering the average of Jan15 - Dec15 and the added the Standard Deviation for the same period. After Green Level is defined, the Red Limit is set using a 20% deviation. The Amber threshold is the remaining range between the Green and the Red threshold. The 20% deviation from the Green to the Red (Limit) represents the buffer permitted by the BOD to the Senior Management to manage the risks without risking the Bank’s capital. Per the Capital Stress Test (CCAR), there is ~20% distance from the baseline to the adverse scenario (stressed) while still maintaining the capital levels above the limits required by the regulator. That ~20% deviation is used from the Green level to the Red (Limit) in the RAS thus integrating the Capital Stress Test (CCAR) into the RAS. | AQ24: =STDEV(AT24:BE24)+(AVERAGE(AT24:BE24)) -> 827.25576 | AR24: =AQ24+1 -> 828.25576 | AS24: =AQ24*1.2 -> 992.70691 | AT24: 836.27936 | AU24: 802.55633 | AV24: 800.59972 | AW24: 801.34267 | AX24: 809.52345 | AY24: 806.86273 | AZ24: 798.30047 | BA24: 790.27428 | BB24: 680.28242 | BC24: 684.70841 | BD24: 658.98479 | BE24: 691.24722 | BF24: 689.08854 | BG24: 687.3231 | BH24: 687.61237 | BR24: =+IFERROR(AVERAGE(AT24:BQ24),"") -> 748.33239 | BS24: =+IFERROR(VAR(AT24:BQ24),"") -> 4177.311 | BW24: Used to be Top 20
C25: # of counterparties with Santander Risk Rating (internal) < 4.5 and exposure>$10MM (PR) | D25: New 2016 | E25: New 2016 | F25: Solvency | H25: Y | L25: Y | P25: Y | Z25: YES | AC25: Monthly | AE25: # of counterparties with Santander Risk Rating (internal) < 4.5 and exposure>$10MM | AF25: Risk MI / Rafael Martínez | AG25: TABLA 1001 | AH25: day 10th of each month depending on Accounting reconciliation | AJ25: Thresholds defined per Historical Data - The average of Jan15 - Dec15 is calculated and the added the Standard Deviation for the same period to define the Green level. In this case since the difference the 20% deviation to the Red Limit is not significant, the gap between the thresholds were be manually adjusted. | AQ25: =STDEV(AT25:BE25)+(AVERAGE(AT25:BE25)) -> 4.2598196 | AR25: 5 | AS25: 6 | AT25: 2 | AU25: 5 | AV25: 5 | AW25: 5 | AX25: 4 | AY25: 2 | AZ25: 1 | BA25: 1 | BB25: 1 | BC25: 1 | BD25: 2 | BE25: 2 | BF25: 2 | BG25: 3 | BH25: 3 | BT25: =+IFERROR(STDEV(AT26:BQ26)*(1-$BS$1),"") -> 5.7074072 | BU25: =+IF(OR(BT25="",OFFSET(AT26,0,MATCH($B$1,AT$2:BQ$2,0)-1)=""),"",IFERROR(IF(ABS(OFFSET(AT26,0,MATCH($B$1,AT$2:BQ$2,0)-1)-OFFSET(AT26,0,MATCH($B$1,AT$2:BQ$2,0)-2))>BT25,"N","µ"),"")) | BV25: Per SBNA methodology for calibration of OCC limit - We set a max $ amount for all industries (e.g. SBNA is $5 bn max per industry), any industry which goes above that needs special approval from the Board; SBNA set the limit as being approx. 50% of SBNA CET1+ACL) | BY25: ?
C26: Industry Exposure (by OCC group) | D26: New 2016 | E26: New 2016 | F26: Solvency | H26: Y | L26: Y | P26: Y | T26: PR analysing Altair system | Y26: 1) Confirm with SHUSA if we can use Outstanding instead of Exposure to be aligned with BSPR local Concentration Guideline. 2) Will this metrics be divided per industry? All the industries will be included in the RAS or just the material industries? 3) Compared the SBNA OCC grouping vs. BSPR current local Concentration Guideline. Overall we can work on the segmentation however in some cases locally we would need another level of segregation (for risk management purposes as well as definition of strategies per our credit policies) which we can later aggregate to reach the SBNA OCC grouping. Groups which BSPR will have a higher level of segregation for further aggregation for the RAS: Government & Education: -Government & Education (Municipalities) -Government & Education (Indirect Risk (PRIDCO)) -Government & Education (Sovereign Risk / Agencies / Public Corp.) -Government & Education (Education) Health Care & Pharmaceuticals -Health Care & Pharmaceuticals (Health Care) -Health Care & Pharmaceuticals (Hospital) Real Estate & Construction -Real Estate & Construction (Commercial Real Estate) -Real Estate & Construction (Construction Developers) Restaurant & Hotel -Hotels and Tourism (Excluding Restaurant) Retail Stores Exc. Food & Drug -Retail Stores Exc. Food & Drug (Retail Sales including Auto Sales and Restaurant) -Retail Stores Exc. Food & Drug (Construction Related) | Z26: YES | AA26: Excludes CRE and Public Sector because there are separate specific metrics to monitor these exposures. SHUSA: Per SBNA methodology for calibration of OCC limit - We set a max $ amount for all industries (e.g. SBNA is $5 bn max per industry), any industry which goes above that needs special approval from the Board; SBNA set the limit as being approx. 50% of SBNA CET1+ACL) BSPR: Currently, the BSPR Concentration Guideline (which is approved by the BOD) has a maximum exposure of 10% (excluding CRE and Public Sector). This means that 10% of our total portfolio would be $3,880MM x 10% = $388MM. Therefore, we would have to apply the max concentration approved by the BOD for an industry to set the Red Limit and apply as a standard max limit for the rest of the industries in order to remain consistent with the BSPR Concentration Guideline. SHUSA said they will discuss further and provide feedback | AC26: Monthly | AE26: Highest industry exposure according to OCC segmentation excluding Realestate & Construction (which includes CRE) and Government and Education (which inclides Public Sector). Excludes CRE and Public Sector because there are specific metrics to monitor those portfolios. | AF26: Concentration Guideline (threshold calibration) Risk MI / Rafael Martínez | AG26: TABLA 1001 | AH26: day 10th of each month depending on Accounting reconciliation | AI26: Concentration Guideline | AJ26: Currently, the BSPR Concentration Guideline (which is approved by the BOD) has a maximum exposure of 10% (excluding CRE and Public Sector). This means that 10% of BSPR total portfolio would be $3,880MM x 10% = $388MM (considered the March 2016 Total Exposure Portfolio of $3,880MM). Therefore, we would have to apply the max concentration approved by the BOD for an industry to set the Red Limit and apply as a standard max limit for the rest of the industries in order to remain consistent with the BSPR Concentration Guideline. After Red Limit is defined, the Green Limit is set using a 20% deviation. The Amber threshold is the remaining range between the Green and the Red threshold. The 20% deviation from the Red (Limit) to the Green level represents the buffer permitted by the BOD to the Senior Management to manage the risks without risking the Bank’s capital. Per the Capital Stress Test (CCAR), there is ~20% distance from the baseline to the adverse scenario (stressed) while still maintaining the capital levels above the limits required by the regulator. That ~20% deviation is used from the Red (Limit) to the Green level in the RAS thus integrating the Capital Stress Test (CCAR) into the RAS. | AQ26: =AS26*(1-0.2) -> 310.4 | AR26: =AQ26+1 -> 311.4 | AS26: =3880*0.1 -> 388 | AZ26: ='Industry Exposure OCC'!H43 -> 314.925 | BB26: ='Industry Exposure OCC'!K43 -> 296.575 | BE26: ='Industry Exposure OCC'!N43 -> 291.76 | BH26: ='Industry Exposure OCC'!T43 -> 290.008 | BR26: =+IFERROR(AVERAGE(AT26:BQ26),"") -> 298.317 | BS26: =+IFERROR(VAR(AT26:BQ26),"") -> 130.29799 | BT26: =+IFERROR(STDEV(AT27:BQ27)*(1-$BS$1),"") -> 17.012161 | BU26: =+IF(OR(BT26="",OFFSET(AT27,0,MATCH($B$1,AT$2:BQ$2,0)-1)=""),"",IFERROR(IF(ABS(OFFSET(AT27,0,MATCH($B$1,AT$2:BQ$2,0)-1)-OFFSET(AT27,0,MATCH($B$1,AT$2:BQ$2,0)-2))>BT26,"N","µ"),"")) -> N | BV26: Pending to confirm with SHUSA how metric will be calibrated. Shouldn't this limit be the same as the 'Industry exposure (by OCC group) (PR)'? The local Concentration Guideline indicates 150% of Tier 1 | BY26: Concentration Guideline
C27: CRE Exposure | D27: New 2016 | E27: New 2016 | F27: Solvency | H27: Y | L27: Y | P27: Y | Y27: Confirm with SHUSA if we can use Outstanding instead of Exposure to be aligned with BSPR local Concentration Guideline. [SA]: As above - align to SBNA | Z27: YES | AC27: Monthly | AE27: CRE exposure - pendiente confirmar cual es la metodología de calculo CRE exposure (excl. Multifamily) (PR) | AF27: Risk MI / Rafael Martínez | AG27: PROBLEMA IDENTIFICANDO STOCK, NO HAY MARCA EN SISTEMA Y LO QUE SE LLEVA ES MANUAL. Data included is Exposure provided by Rafa in 0000 RISK TOLERANCE | AH27: day 10th of each month depending on Accounting reconciliation | AI27: Concentration Guideline | AJ27: Currently, the BSPR Concentration Guideline (which is approved by the BOD) has a maximum exposure of 28% for the industry of CRE (portfolio with the highest allowed concentration). This means that 28% of our total portfolio would be $3,880MM x 28% = $1,086MM (considered the March 2016 Total Exposure Portfolio of $3,880MM). Therefore, we would have to apply the max concentration approved by the BOD for an industry to set the Red Limit and apply as a standard max limit for the rest of the industries in order to remain consistent with the BSPR Concentration Guideline. After Red Limit is defined, the Green Limit is set using a 20% deviation. The Amber threshold is the remaining range between the Green and the Red threshold. The 20% deviation from the Green to the Red (Limit) represents the buffer permitted by the BOD to the Senior Management to manage the risks without risking the Bank’s capital. Per the Capital Stress Test (CCAR), there is ~20% distance from the baseline to the adverse scenario (stressed) while still maintaining the capital levels above the limits required by the regulator. That ~20% deviation is used from the Red level (Limit) to the Green in the RAS thus integrating the Capital Stress Test (CCAR) into the RAS | AQ27: =AS27*(1-0.2) -> 869.12 | AR27: =AQ27+1 -> 870.12 | AS27: =3880*0.28 -> 1086.4 | AT27: 559.48319 | AU27: 565.52119 | AV27: 570.67219 | AW27: 583.10147 | AX27: 613.8976 | AY27: 611.92483 | AZ27: 614.45283 | BA27: 607.52577 | BB27: 602.1959 | BC27: 599.09236 | BD27: 598.03638 | BE27: 587.22652 | BF27: 590.60458 | BG27: 510.02835 | BH27: 508.19472 | BR27: =+IFERROR(AVERAGE(AT27:BQ27),"") -> 581.46386 | BS27: =+IFERROR(VAR(AT27:BQ27),"") -> 1157.6545 | BT27: =+IFERROR(STDEV(AT28:BQ28)*(1-$BS$1),"") -> 33.353077 | BU27: =+IF(OR(BT27="",OFFSET(AT28,0,MATCH($B$1,AT$2:BQ$2,0)-1)=""),"",IFERROR(IF(ABS(OFFSET(AT28,0,MATCH($B$1,AT$2:BQ$2,0)-1)-OFFSET(AT28,0,MATCH($B$1,AT$2:BQ$2,0)-2))>BT27,"N","µ"),"")) -> µ | BV27: Pending to confirm with SHUSA how metric will be calibrated. Shouldn't this limit be the same as the 'Industry exposure (by OCC group) (PR)'? The local Concentration Guideline indicates 75% of Tier 1 | BY27: Aplicamos el max de CRE
C28: Public Sector Exposure | D28: New 2016 | E28: New 2016 | F28: Solvency | H28: Y | L28: Y | P28: Y | Y28: Metric was change from 'Institutional exposure (PR)' to 'Public sector exposure (PR)' in order to include all exposure with PR government, municipalities, government agencies, etc. [SA]: OK Confirm with SHUSA if we can use Outstanding instead of Exposure to be aligned with local Concentration Guideline. Concenration Guideline presented Quarterly. [SA]: As above - align to SBNA | Z28: YES | AC28: Monthly | AE28: Total Exposure equals Drawn plus Available plus Contingencies for PR Government, Municipalities, Government Agencies, etc. | AF28: Risk MI / Rafael Martínez | AG28: TABLA 1001 | AH28: day 10th of each month depending on Accounting reconciliation | AI28: Concentration Guideline | AJ28: Currently, the BSPR Concentration Guideline (which is approved by the BOD) has a maximum exposure of 14% for the Public Sector. This means that 14% of our total portfolio would be $3,880MM x 14% = $543MM (considered the March 2016 Total Exposure Portfolio of $3,880MM). Therefore, we would have to apply the max concentration approved by the BOD for an industry to set the Red Limit and apply as a standard max limit for the rest of the industries in order to remain consistent with the BSPR Concentration Guideline. After Red Limit is defined, the Green Limit is set using a 20% deviation. The Amber threshold is the remaining range between the Green and the Red threshold. The 20% deviation from the Green to the Red (Limit) represents the buffer permitted by the BOD to the Senior Management to manage the risks without risking the Bank’s capital. Per the Capital Stress Test (CCAR), there is ~20% distance from the baseline to the adverse scenario (stressed) while still maintaining the capital levels above the limits required by the regulator. That ~20% deviation is used from the Red level (Limit) to the Green in the RAS thus integrating the Capital Stress Test (CCAR) into the RAS. | AQ28: =AS28*(1-0.2) -> 434.56 | AR28: =AQ28+1 -> 435.56 | AS28: =3880*0.14 -> 543.2 | AT28: 474.77383 | AU28: 471.88535 | AV28: 471.47619 | AW28: 471.08293 | AX28: 468.20172 | AY28: 460.37746 | AZ28: 456.86937 | BA28: 453.97987 | BB28: 326.12961 | BC28: 325.71993 | BD28: 321.74299 | BE28: 349.69984 | BF28: 349.13849 | BG28: 348.5808 | BH28: 347.97281 | BR28: =+IFERROR(AVERAGE(AT28:BQ28),"") -> 406.50875 | BS28: =+IFERROR(VAR(AT28:BQ28),"") -> 4449.7109 | BT28: =+IFERROR(STDEV(AT29:BQ29)*(1-$BS$1),"") | BU28: =+IF(OR(BT28="",OFFSET(AT29,0,MATCH($B$1,AT$2:BQ$2,0)-1)=""),"",IFERROR(IF(ABS(OFFSET(AT29,0,MATCH($B$1,AT$2:BQ$2,0)-1)-OFFSET(AT29,0,MATCH($B$1,AT$2:BQ$2,0)-2))>BT28,"N","µ"),""))
B29: Liquidity / Funding Risk | C29: Stressed Survival Period (days) | D29: 90 | E29: 60 | F29: Market Risk | H29: Y | L29: Y | P29: Y | Z29: YES | AA29: Historical Data is not available as this is a newly implemented metric | AC29: Monthly | AE29: The amount of days remaining until there is a cash shortfall under stressed conditions. | AF29: Market Risk / Marilena Castro | AG29: Metric is stored in EXCEL in a Local Network. Currently data is extracted from Balance Sheet statements for BSPR, SSC LLC and BanCorp, OFSA system, NMD Calculador (corporate system), which are consolidated into one spreadsheet (Excel). As part of the Market Risk Efficiency Plan, a server is being developed in which this data will be stored. | AH29: The availability depends on ALCO Committee date towards the end of the month. | AI29: Liquidity Policy | AJ29: Liquidity Policy Pending updated Liquidity Policy, triggers and limits provided by Market Risk Department according to analysis and presentation done and approved by the Board on February 2016. Refer to document Market Risk 2016 Limits Analysis v2 - Copy.docx, section 2.2. The Local Limit 2016 was set as the Ambar trigger and the 2016 RAS was set as the Red limit. | AL29: Market Risk Update Risk Committee as Liquidity Horizon ALCO Risk Scorecard | AQ29: > 90 days | AR29: < 90 days | AS29: <= 60 days | AT29: N/Avail | AU29: N/Avail | AV29: N/Avail | AW29: N/Avail | AX29: N/Avail | AY29: N/Avail | AZ29: N/Avail | BA29: N/Avail | BB29: N/Avail | BC29: N/Avail | BD29: N/Avail | BE29: > 90 days | BF29: N/Avail | BG29: N/Avail | BH29: > 90 days | BR29: =+IFERROR(AVERAGE(AT29:BQ29),"") | BS29: =+IFERROR(VAR(AT29:BQ29),"") | BT29: =+IFERROR(STDEV(AT30:BQ30)*(1-$BS$1),"") -> 0.011265596 | BU29: =+IF(OR(BT29="",OFFSET(AT30,0,MATCH($B$1,AT$2:BQ$2,0)-1)=""),"",IFERROR(IF(ABS(OFFSET(AT30,0,MATCH($B$1,AT$2:BQ$2,0)-1)-OFFSET(AT30,0,MATCH($B$1,AT$2:BQ$2,0)-2))>BT29,"N","µ"),"")) -> µ
